[2022-12-26T07:19:47.873+0000] {taskinstance.py:1165} INFO - Dependencies all met for <TaskInstance: bertopic_autopik_airflow.raw_data_preprocess manual__2022-12-26T07:19:29.877729+00:00 [queued]>
[2022-12-26T07:19:47.886+0000] {taskinstance.py:1165} INFO - Dependencies all met for <TaskInstance: bertopic_autopik_airflow.raw_data_preprocess manual__2022-12-26T07:19:29.877729+00:00 [queued]>
[2022-12-26T07:19:47.886+0000] {taskinstance.py:1362} INFO - 
--------------------------------------------------------------------------------
[2022-12-26T07:19:47.886+0000] {taskinstance.py:1363} INFO - Starting attempt 1 of 1
[2022-12-26T07:19:47.886+0000] {taskinstance.py:1364} INFO - 
--------------------------------------------------------------------------------
[2022-12-26T07:19:47.902+0000] {taskinstance.py:1383} INFO - Executing <Task(PythonOperator): raw_data_preprocess> on 2022-12-26 07:19:29.877729+00:00
[2022-12-26T07:19:47.910+0000] {standard_task_runner.py:54} INFO - Started process 144 to run task
[2022-12-26T07:19:47.914+0000] {standard_task_runner.py:82} INFO - Running: ['***', 'tasks', 'run', 'bertopic_autopik_***', 'raw_data_preprocess', 'manual__2022-12-26T07:19:29.877729+00:00', '--job-id', '5', '--raw', '--subdir', 'DAGS_FOLDER/bertopic_autopik_***.py', '--cfg-path', '/tmp/tmp6l758xz2']
[2022-12-26T07:19:47.914+0000] {standard_task_runner.py:83} INFO - Job 5: Subtask raw_data_preprocess
[2022-12-26T07:19:47.915+0000] {dagbag.py:525} INFO - Filling up the DagBag from /opt/***/dags/bertopic_autopik_***.py
[2022-12-26T07:19:58.899+0000] {warnings.py:109} WARNING - /home/***/.local/lib/python3.8/site-packages/***/configuration.py:545: DeprecationWarning: The sql_alchemy_conn option in [core] has been moved to the sql_alchemy_conn option in [database] - the old setting has been used, but please update your config.
  option = self._get_environment_variables(deprecated_key, deprecated_section, key, section)

[2022-12-26T07:19:59.040+0000] {task_command.py:384} INFO - Running <TaskInstance: bertopic_autopik_airflow.raw_data_preprocess manual__2022-12-26T07:19:29.877729+00:00 [running]> on host c4b524c24ec1
[2022-12-26T07:19:59.232+0000] {taskinstance.py:1590} INFO - Exporting the following env vars:
AIRFLOW_CTX_DAG_EMAIL=hojun.seo@pikurate.com
AIRFLOW_CTX_DAG_OWNER=***
AIRFLOW_CTX_DAG_ID=bertopic_autopik_***
AIRFLOW_CTX_TASK_ID=raw_data_preprocess
AIRFLOW_CTX_EXECUTION_DATE=2022-12-26T07:19:29.877729+00:00
AIRFLOW_CTX_TRY_NUMBER=1
AIRFLOW_CTX_DAG_RUN_ID=manual__2022-12-26T07:19:29.877729+00:00
[2022-12-26T07:20:15.414+0000] {taskinstance.py:1851} ERROR - Task failed with exception
Traceback (most recent call last):
  File "/home/airflow/.local/lib/python3.8/site-packages/airflow/operators/python.py", line 175, in execute
    return_value = self.execute_callable()
  File "/home/airflow/.local/lib/python3.8/site-packages/airflow/operators/python.py", line 193, in execute_callable
    return self.python_callable(*self.op_args, **self.op_kwargs)
  File "/opt/airflow/dags/functions/data.py", line 461, in raw_data_preprocess
    user_lang_dict, pik_lang_dict, link_lang_dict, pik_status_dict, link_cat_pik = dropNa_dropArtificialUser(link_cat_pik, artificial_users, dropna=True, drop_artificial=True, integering=True)
  File "/opt/airflow/dags/functions/data.py", line 418, in dropNa_dropArtificialUser
    slug1 = data['slug'][data['pik_id'] == 3085].iloc[0]
  File "/home/airflow/.local/lib/python3.8/site-packages/pandas/core/indexing.py", line 967, in __getitem__
    return self._getitem_axis(maybe_callable, axis=axis)
  File "/home/airflow/.local/lib/python3.8/site-packages/pandas/core/indexing.py", line 1523, in _getitem_axis
    self._validate_integer(key, axis)
  File "/home/airflow/.local/lib/python3.8/site-packages/pandas/core/indexing.py", line 1455, in _validate_integer
    raise IndexError("single positional indexer is out-of-bounds")
IndexError: single positional indexer is out-of-bounds
[2022-12-26T07:20:15.424+0000] {taskinstance.py:1401} INFO - Marking task as FAILED. dag_id=bertopic_autopik_***, task_id=raw_data_preprocess, execution_date=20221226T071929, start_date=20221226T071947, end_date=20221226T072015
[2022-12-26T07:20:15.804+0000] {standard_task_runner.py:102} ERROR - Failed to execute job 5 for task raw_data_preprocess (single positional indexer is out-of-bounds; 144)
[2022-12-26T07:20:15.992+0000] {local_task_job.py:164} INFO - Task exited with return code 1
[2022-12-26T07:20:16.063+0000] {local_task_job.py:273} INFO - 0 downstream tasks scheduled from follow-on schedule check
